<article class="bugdoc">
    <h2 class="bugdoc-title" id="Bug-Doc:PE0045">PE0045: Uncaught Except</h2>
    <h3>A C++ exception is thrown and never caught. </h3>
    <section id="tip">
     <h4 style="border-top: 0pt; padding: 0pt 4pt 4pt 4pt;">Bug info</h4>
                <dl>
                    <dt>BugTypeID</dt>
                    <dd>PE0045</dd>
                    <dt>Tags</dt>
                    <dd>CPP</dd>
                    <dt>Category</dt>
                    <dd>Checkers/CPP</dd>
                    <dt>Authors</dt>
                    <dd>pinpoint</dd>
                </dl>
    <h4>Description</h4>
<p>A C++ exception is thrown and never caught. 
Such exceptions can result in program crashes because they force a call to unexpected(), which typically terminates the program.</p>
<p>For example:</p>
<ul>
<li>An exception that is not allowed by the exception specification of a function is thrown.</li>
<li>An exception is thrown from a root function. By default, a root function is defined as having no known callers, and its name matches the following regular expression: 
<code>((((^|_)m|M)ain)|(^MAIN))$</code></li>
</ul>
<p>The preceding regular expression matches main, WinMain, MAIN. It does not match DOMAIN.</p>
<h4>Vulnerability and risk</h4>
<h5>program crashes</h5>
<p>When an exception is not caught, it may cause the program to crash or expose sensitive information.</p>
<h4>Likelihood of Exploit</h4>
<p>Medium</p>
<h4>Potential Mitigations</h4>
<p>Handle all exceptions.</p>
<h4>Demonstrative Examples</h4>
<h5>Vulnerable Code Example</h5>
<div class="highlight"><pre><span></span><span class="kt">void</span> <span class="nf">fun</span><span class="p">()</span> <span class="p">{</span>
  <span class="k">throw</span> <span class="mi">7</span><span class="p">;</span>
<span class="p">}</span>

<span class="kt">int</span> <span class="nf">bad</span><span class="p">(){</span>
  <span class="n">fun</span><span class="p">();</span>
  <span class="k">return</span> <span class="mi">0</span><span class="p">;</span>
<span class="p">}</span>
</pre></div>
<p>In the vulnerable code example, the bad() function doesn't catch exception thrown by fun().</p>
<h5>Fixed Code Example</h5>
<div class="highlight"><pre><span></span><span class="kt">void</span> <span class="nf">fun</span><span class="p">()</span> <span class="p">{</span>
  <span class="k">throw</span> <span class="mi">7</span><span class="p">;</span>
<span class="p">}</span>

<span class="kt">int</span> <span class="nf">good</span><span class="p">(){</span>
  <span class="k">try</span> <span class="p">{</span>
    <span class="n">fun</span><span class="p">();</span>
  <span class="p">}</span> <span class="k">catch</span> <span class="p">(...)</span> <span class="p">{</span>
    <span class="c1">// Handle error</span>
  <span class="p">}</span>
<span class="p">}</span>
</pre></div>
<p>In the invulnerable code example, the good() function handles all exceptions.</p>

    </section>
</article>
